Workbook

Sheet 1. Datos Entrada
A1: METODOLOGÍA MCDM-LCA PARA SELECCIÓN DE MATERIALES SOSTENIBLES
A3: TABLA I – Datos de entrada para los tres métodos de ponderación (N = 34 fuentes)
A4: Criterio | B4: Cantidad menciones | C4: Score Total
A5: Emisiones de CO₂ equivalente – Potencial de Calentamiento Global (GWP) | B5: 30 | C5: =(B5/34) -> 0.88235294
A6: Energía Embebida | B6: 16 | C6: =(B6/34) -> 0.47058824
A7: Desempeño Técnico y Mecánico | B7: 14 | C7: =(B7/34) -> 0.41176471
A8: Costo del Ciclo de Vida (Life Cycle Cost – LCC) | B8: 11 | C8: =(B8/34) -> 0.32352941
A9: Impacto en Salud Humana y Ecosistemas (toxicidad y biodiversidad) | B9: 5 | C9: =(B9/34) -> 0.14705882
A10: Total | C10: =SUM(C5:C9) -> 2.2352941

Sheet 2.M1 Frecuencia Ponderada
A1: M1 – FRECUENCIA PONDERADA
A3: Criterio | B3: Score Total | C3: Σ Score Total | D3: M1 (%)
A4: Emisiones de CO₂ equivalente – Potencial de Calentamiento Global (GWP) | B4: ='1. Datos Entrada'!C5 -> 0.88235294 | C4: ='1. Datos Entrada'!C10 -> 2.2352941 | D4: =B4/C4 -> 0.39473684
A5: Energía Embebida | B5: ='1. Datos Entrada'!C6 -> 0.47058824 | C5: ='1. Datos Entrada'!C10 -> 2.2352941 | D5: =B5/C5 -> 0.21052632
A6: Desempeño Técnico y Mecánico | B6: ='1. Datos Entrada'!C7 -> 0.41176471 | C6: ='1. Datos Entrada'!C10 -> 2.2352941 | D6: =B6/C6 -> 0.18421053
A7: Costo del Ciclo de Vida (Life Cycle Cost – LCC) | B7: ='1. Datos Entrada'!C8 -> 0.32352941 | C7: ='1. Datos Entrada'!C10 -> 2.2352941 | D7: =B7/C7 -> 0.14473684
A8: Impacto en Salud Humana y Ecosistemas (toxicidad y biodiversidad) | B8: ='1. Datos Entrada'!C9 -> 0.14705882 | C8: ='1. Datos Entrada'!C10 -> 2.2352941 | D8: =B8/C8 -> 0.065789474
A9: TOTAL | D9: =SUM(D4:D8) -> 1

Sheet 3.M2 Entropia Shannon
A1: M2 – ENTROPÍA DE SHANNON
A2: Fórmula: Hi = -Σ pij·ln(pij) | wi = (Hmax – Hi) / Σ(Hmax – Hj)
A4: Criterio | B4: p(●)=●/34 | C4: p(–)=–/34 | D4: -p(●)·ln(p(●)) | E4: -p(–)·ln(p(–)) | F4: Hi (Entropía) | G4: M2 (%)
A5: Emisiones de CO₂ equivalente – Potencial de Calentamiento Global (GWP) | B5: ='1. Datos Entrada'!B5/34 -> 0.88235294 | C5: =(34-'1. Datos Entrada'!B5)/34 -> 0.11764706 | D5: =IF(B5>0,-B5*LN(B5),0) -> 0.11043807 | E5: =IF(C5>0,-C5*LN(C5),0) -> 0.25177249 | F5: =D5+E5 -> 0.36221056 | G5: =(LN(34)-F5)/(5*LN(34)-SUM(F5:F9)) -> 0.21302233
A6: Energía Embebida | B6: ='1. Datos Entrada'!B6/34 -> 0.47058824 | C6: =(34-'1. Datos Entrada'!B6)/34 -> 0.52941176 | D6: =IF(B6>0,-B6*LN(B6),0) -> 0.35471614 | E6: =IF(C6>0,-C6*LN(C6),0) -> 0.33669994 | F6: =D6+E6 -> 0.69141608 | G6: =(LN(34)-F6)/(5*LN(34)-SUM(F5:F9)) -> 0.19085899
A7: Desempeño Técnico y Mecánico | B7: ='1. Datos Entrada'!B7/34 -> 0.41176471 | C7: =(34-'1. Datos Entrada'!B7)/34 -> 0.58823529 | D7: =IF(B7>0,-B7*LN(B7),0) -> 0.36536014 | E7: =IF(C7>0,-C7*LN(C7),0) -> 0.31213427 | F7: =D7+E7 -> 0.6774944 | G7: =(LN(34)-F7)/(5*LN(34)-SUM(F5:F9)) -> 0.19179625
A8: Costo del Ciclo de Vida (Life Cycle Cost – LCC) | B8: ='1. Datos Entrada'!B8/34 -> 0.32352941 | C8: =(34-'1. Datos Entrada'!B8)/34 -> 0.67647059 | D8: =IF(B8>0,-B8*LN(B8),0) -> 0.3650917 | E8: =IF(C8>0,-C8*LN(C8),0) -> 0.26440956 | F8: =D8+E8 -> 0.62950126 | G8: =(LN(34)-F8)/(5*LN(34)-SUM(F5:F9)) -> 0.19502733
A9: Impacto en Salud Humana y Ecosistemas (toxicidad y biodiversidad) | B9: ='1. Datos Entrada'!B9/34 -> 0.14705882 | C9: =(34-'1. Datos Entrada'!B9)/34 -> 0.85294118 | D9: =IF(B9>0,-B9*LN(B9),0) -> 0.28190038 | E9: =IF(C9>0,-C9*LN(C9),0) -> 0.13567283 | F9: =D9+E9 -> 0.41757321 | G9: =(LN(34)-F9)/(5*LN(34)-SUM(F5:F9)) -> 0.20929511
A10: TOTAL | G10: =SUM(G5:G9) -> 1

Sheet 4.M3 AHP Simplificado
A1: M3 – AHP SIMPLIFICADO (Analytical Hierarchy Process)
A3: Matriz de comparación por pares (aij = ●i / ●j) | B3: CO₂/GWP | C3: Energ.Emb | D3: Desem.Téc | E3: Costo LCC | F3: Salud/Eco | G3: Suma fila | H3: M3 (%)
A4: Emisiones de CO₂ equivalente – Potencial de Calentamiento Global (GWP) | B4: ='1. Datos Entrada'!B5/'1. Datos Entrada'!B5 -> 1 | C4: ='1. Datos Entrada'!B5/'1. Datos Entrada'!B6 -> 1.875 | D4: ='1. Datos Entrada'!B5/'1. Datos Entrada'!B7 -> 2.1428571 | E4: ='1. Datos Entrada'!B5/'1. Datos Entrada'!B8 -> 2.7272727 | F4: ='1. Datos Entrada'!B5/'1. Datos Entrada'!B9 -> 6 | G4: =SUM(B4:F4) -> 13.74513 | H4: =G4/SUM(G4:G8) -> 0.39473684
A5: Energía Embebida | B5: ='1. Datos Entrada'!B6/'1. Datos Entrada'!B5 -> 0.53333333 | C5: ='1. Datos Entrada'!B6/'1. Datos Entrada'!B6 -> 1 | D5: ='1. Datos Entrada'!B6/'1. Datos Entrada'!B7 -> 1.1428571 | E5: ='1. Datos Entrada'!B6/'1. Datos Entrada'!B8 -> 1.4545455 | F5: ='1. Datos Entrada'!B6/'1. Datos Entrada'!B9 -> 3.2 | G5: =SUM(B5:F5) -> 7.3307359 | H5: =G5/SUM(G4:G8) -> 0.21052632
A6: Desempeño Técnico y Mecánico | B6: ='1. Datos Entrada'!B7/'1. Datos Entrada'!B5 -> 0.46666667 | C6: ='1. Datos Entrada'!B7/'1. Datos Entrada'!B6 -> 0.875 | D6: ='1. Datos Entrada'!B7/'1. Datos Entrada'!B7 -> 1 | E6: ='1. Datos Entrada'!B7/'1. Datos Entrada'!B8 -> 1.2727273 | F6: ='1. Datos Entrada'!B7/'1. Datos Entrada'!B9 -> 2.8 | G6: =SUM(B6:F6) -> 6.4143939 | H6: =G6/SUM(G4:G8) -> 0.18421053
A7: Costo del Ciclo de Vida (Life Cycle Cost – LCC) | B7: ='1. Datos Entrada'!B8/'1. Datos Entrada'!B5 -> 0.36666667 | C7: ='1. Datos Entrada'!B8/'1. Datos Entrada'!B6 -> 0.6875 | D7: ='1. Datos Entrada'!B8/'1. Datos Entrada'!B7 -> 0.78571429 | E7: ='1. Datos Entrada'!B8/'1. Datos Entrada'!B8 -> 1 | F7: ='1. Datos Entrada'!B8/'1. Datos Entrada'!B9 -> 2.2 | G7: =SUM(B7:F7) -> 5.039881 | H7: =G7/SUM(G4:G8) -> 0.14473684
A8: Impacto en Salud Humana y Ecosistemas (toxicidad y biodiversidad) | B8: ='1. Datos Entrada'!B9/'1. Datos Entrada'!B5 -> 0.16666667 | C8: ='1. Datos Entrada'!B9/'1. Datos Entrada'!B6 -> 0.3125 | D8: ='1. Datos Entrada'!B9/'1. Datos Entrada'!B7 -> 0.35714286 | E8: ='1. Datos Entrada'!B9/'1. Datos Entrada'!B8 -> 0.45454545 | F8: ='1. Datos Entrada'!B9/'1. Datos Entrada'!B9 -> 1 | G8: =SUM(B8:F8) -> 2.290855 | H8: =G8/SUM(G4:G8) -> 0.065789474
A9: TOTAL | H9: =SUM(H4:H8) -> 1

Sheet 5. Peso Final Combinado
A1: PESO FINAL COMBINADO – w_final = 0.40·M1 + 0.30·M2 + 0.30·M3
A2: Ponderación M1 → | B2: 0.4 | C2: Ponderación M2 → | D2: 0.3 | E2: Ponderación M3 → | F2: 0.3 | G2: Suma →
A3: Criterio | B3: M1 – Frec.Ponderada | C3: M2 – Entropía Shannon | D3: M3 – AHP Simplificado | E3: PESO FINAL (combinado)
A4: Emisiones de CO₂ equivalente – Potencial de Calentamiento Global (GWP) | B4: ='2.M1 Frecuencia Ponderada'!D4 -> 0.39473684 | C4: ='3.M2 Entropia Shannon'!G5 -> 0.21302233 | D4: ='4.M3 AHP Simplificado'!H4 -> 0.39473684 | E4: =$B$2*B4+$D$2*C4+$F$2*D4 -> 0.34022249
A5: Energía Embebida | B5: ='2.M1 Frecuencia Ponderada'!D5 -> 0.21052632 | C5: ='3.M2 Entropia Shannon'!G6 -> 0.19085899 | D5: ='4.M3 AHP Simplificado'!H5 -> 0.21052632 | E5: =$B$2*B5+$D$2*C5+$F$2*D5 -> 0.20462612
A6: Desempeño Técnico y Mecánico | B6: ='2.M1 Frecuencia Ponderada'!D6 -> 0.18421053 | C6: ='3.M2 Entropia Shannon'!G7 -> 0.19179625 | D6: ='4.M3 AHP Simplificado'!H6 -> 0.18421053 | E6: =$B$2*B6+$D$2*C6+$F$2*D6 -> 0.18648624
A7: Costo del Ciclo de Vida (Life Cycle Cost – LCC) | B7: ='2.M1 Frecuencia Ponderada'!D7 -> 0.14473684 | C7: ='3.M2 Entropia Shannon'!G8 -> 0.19502733 | D7: ='4.M3 AHP Simplificado'!H7 -> 0.14473684 | E7: =$B$2*B7+$D$2*C7+$F$2*D7 -> 0.15982399
A8: Impacto en Salud Humana y Ecosistemas (toxicidad y biodiversidad) | B8: ='2.M1 Frecuencia Ponderada'!D8 -> 0.065789474 | C8: ='3.M2 Entropia Shannon'!G9 -> 0.20929511 | D8: ='4.M3 AHP Simplificado'!H8 -> 0.065789474 | E8: =$B$2*B8+$D$2*C8+$F$2*D8 -> 0.10884116
A9: TOTAL | B9: =SUM(B4:B8) -> 1 | C9: =SUM(C4:C8) -> 1 | D9: =SUM(D4:D8) -> 1 | E9: =SUM(E4:E8) -> 1
E16: CO₂/GWP es el criterio dominante en los tres métodos, especialmente en AHP (39.5%)

Sheet 6. Matriz 34 Fuentes
A1: TABLA III – Matriz MCDM de 34 fuentes con pesos estadísticamente calculados por criterio
A2: ● = Mencionado en la literatura (profundidad analítica) | – = No abordado
A3: # | B3: Autores / Referencia | C3: CO₂ (GWP)Emisiones de CO₂ equivalente – Potencial de Calentamiento Global (GWP) 24.47% | D3: Energía Embebida 21.88% | E3: Desempeño Técnico y Mecánico 20.96% | F3: Costo del Ciclo de Vida (Life Cycle Cost – LCC) 19.17% | G3: Impacto en Salud Humana y Ecosistemas (toxicidad y biodiversidad) 13.51% | H3: Aporte a la Tesis
A4: BLOQUE BASE – FUENTES ORIGINALES (Objetivo Específico 1)
A5: 1 | B5: Adesope, Ostręga & Borowski (2025) | C5: ● | D5: – | E5: ● | F5: ● | G5: – | H5: BIM-LCA integrado para reducción de huella de carbono.
A6: 2 | B6: Arab, Raouf, Rahal et al. (2025) | C6: ● | D6: – | E6: ● | F6: – | G6: – | H6: LCA en edificación industrial con OneClick LCA.
A7: 3 | B7: Takano & Aiki (2025) | C7: ● | D7: – | E7: – | F7: ● | G7: ● | H7: MCDA multicriterio para selección sostenible.
A8: 4 | B8: Dinh, Dinh & Götze (2020) | C8: ● | D8: – | E8: ● | F8: – | G8: – | H8: Integración de criterios de sostenibilidad en selección.
A9: 5 | B9: Elshoubaky, Elbeltagi et al. (2024) | C9: ● | D9: ● | E9: ● | F9: – | G9: – | H9: Dinámica de sistemas + TOPSIS. Valida técnica MCDM.
A10: 6 | B10: Huang, Lin, Chen et al. (2025) | C10: ● | D10: ● | E10: – | F10: – | G10: – | H10: Impacto ambiental y huella de carbono vía LCA.
A11: 7 | B11: Ugural, Ozyilmaz & Burgan (2024) | C11: ● | D11: – | E11: – | F11: – | G11: – | H11: LCA en edificios aeroportuarios sostenibles.
A12: 8 | B12: Ben Rjiba, Tóth-Nagy et al. (2026) | C12: ● | D12: – | E12: ● | F12: – | G12: – | H12: Evaluación ambiental comparativa de materiales.
A13: 9 | B13: Demirtürk, Ahıskalı et al. (2025) | C13: – | D13: – | E13: ● | F13: – | G13: – | H13: Análisis multicriterio de polvo de granito en compuestos.
A14: 10 | B14: Mekky, Ibrahim et al. (2025) | C14: ● | D14: – | E14: ● | F14: ● | G14: ● | H14: TOPSIS para biochar en concreto: beneficios ambientales.
A15: 11 | B15: Rey-Álvarez, Silvestre et al. (2025) | C15: – | D15: – | E15: – | F15: ● | G15: – | H15: Evaluación comparativa de toxicidad en materiales vía LCA.
A16: 12 | B16: Silva, Figueiredo, Najjar et al. (2024) | C16: ● | D16: ● | E16: ● | F16: ● | G16: ● | H16: LCA + optimización multicriterio en concreto reciclado.
A17: 13 | B17: Luque Castillo & Yepes (2025) | C17: ● | D17: ● | E17: ● | F17: ● | G17: ● | H17: LCA en vivienda social: enfoque multicriterio integral.
A18: BLOQUE A – MCDM AVANZADO (Decisión real con TOPSIS / MCDA)
A19: 14 | B19: Bhattarai, Bhattarai et al. (2024) | C19: ● | D19: ● | E19: – | F19: – | G19: – | H19: LCA de edificios residenciales en Nepal.
A20: 15 | B20: Ungureanu, Sola, Neri et al. (2025) | C20: ● | D20: – | E20: – | F20: – | G20: – | H20: Emisiones CO₂ en etapa de cocción de cerámicos.
A21: 16 | B21: Kocaer (2025) | C21: ● | D21: ● | E21: – | F21: – | G21: – | H21: Evaluación ambiental en impresión 3D.
A22: 17 | B22: Serrano-Baena, Ruiz-Díaz et al. (2025) | C22: ● | D22: ● | E22: ● | F22: ● | G22: – | H22: MLCAQ + BIM para edificios complejos. Metodología híbrida.
A23: 18 | B23: Shang, Shi, Li et al. (2025) | C23: ● | D23: – | E23: – | F23: ● | G23: – | H23: Sinergia costo-carbono en paja reciclada como material.
A24: BLOQUE B – LCA + ENERGÍA EMBEBIDA
A25: 19 | B25: Javan, Chaggar, Darestani et al. (2025) | C25: – | D25: – | E25: ● | F25: – | G25: – | H25: Trabajabilidad del concreto geopolimérico.
A26: 20 | B26: Qi, Yuan, Shang et al. (2025) | C26: ● | D26: ● | E26: ● | F26: – | G26: – | H26: Diseño y LCA de bloques de tierra estabilizada con residuos.
A27: 21 | B27: Janpetch, Trakolkul et al. (2025) | C27: ● | D27: ● | E27: ● | F27: – | G27: – | H27: Emisiones y desempeño térmico de ladrillos sin cocción.
A28: 22 | B28: Duan, Omrany & Zuo (2024) | C28: ● | D28: ● | E28: – | F28: – | G28: – | H28: GHG embebidos en construcción de madera masiva.
A29: BLOQUE C – TÉCNICO + OPTIMIZACIÓN
A30: 23 | B30: Li Ren, Ru, Xiao & Ju (2024) | C30: – | D30: ● | E30: – | F30: – | G30: ● | H30: Optimización multicriterio con énfasis en energía y ecosistemas.
A31: 24 | B31: Ben Rjiba et al. – vidrio/biochar (2026) | C31: ● | D31: – | E31: ● | F31: – | G31: – | H31: Evaluación de vidrio reciclado y biochar. Criterio técnico.
A32: BLOQUE D – SALUD / TOXICIDAD / ECOSISTEMAS (Frontera técnica 2024-2026)
A33: 25 | B33: Vite & Alipour (2023) | C33: ● | D33: ● | E33: – | F33: – | G33: – | H33: Integración BIM-LCA comparativa de materiales.
A34: 26 | B34: Zhang, Liu & Wang (2024) | C34: ● | D34: – | E34: – | F34: ● | G34: – | H34: AHP-TOPSIS + big data para selección sostenible.
A35: 27 | B35: Hernández, Muñoz & Castro (2020) | C35: ● | D35: ● | E35: – | F35: – | G35: – | H35: Big data + MCDM en construcción sostenible.
A36: 28 | B36: Yu, Zhang & Wang (2022) | C36: ● | D36: – | E36: – | F36: ● | G36: – | H36: Selección de materiales con MCDM y Big Data.
A37: 29 | B37: Liao & Zhang (2024) | C37: ● | D37: – | E37: – | F37: – | G37: – | H37: Ciudades inteligentes y economía circular.
A38: 30 | B38: Chen (2021) | C38: ● | D38: – | E38: – | F38: ● | G38: – | H38: Optimización de selección con analítica ambiental.
A39: 31 | B39: Zhang, Li & Zhao (2021) | C39: ● | D39: ● | E39: – | F39: – | G39: – | H39: LCA con big data de materiales reciclados urbanos.
A40: 32 | B40: Ma, Zhang & Wang (2021) | C40: ● | D40: ● | E40: – | F40: – | G40: – | H40: Emisiones de ciclo de vida: meta-análisis global.
...

Sheet 7. Matriz Datos Entrada
A1: DATOS DE ENTRADA – MATERIALES SOSTENIBLES (8 candidatos)
A2: Valores de desempeño por criterio extraídos de literatura 2020-2026 | N=34 fuentes | CO₂: kg CO₂-eq/ton | Energía: MJ/kg | Técnico: índice 0-10 | Costo LCC: índice 1-10 | Salud/Eco: índice 1-5
A4: # | B4: Material | C4: Emisiones de CO₂ equivalente – Potencial de Calentamiento Global (GWP) (kg CO₂-eq/ton) | D4: Energía Embebida (MJ/kg) | E4: Desempeño Técnico y Mecánico | F4: Costo del Ciclo de Vida (Life Cycle Cost – LCC) | G4: Impacto en Salud Humana y Ecosistemas (toxicidad y biodiversidad) | H4: Cantidad menciones | I4: Disponibilidad Mercado Local (CO)
A5: 1 | B5: Concreto con Agregados de Concreto Reciclado (Residuos de Construcción y Demolición – RCD) | C5: 320 | D5: 1.2 | E5: 7.5 | F5: 4 | G5: 3.5 | H5: 18 | I5: Alta - disponible en Colombia (RCD urbano)
A6: 2 | B6: Geopolímeros Activados Alcalinamente (base escoria de alto horno y/o ceniza volante) | C6: 100 | D6: 3.5 | E6: 8 | F6: 6 | G6: 3 | H6: 14 | I6: Parcial - requiere industrialización local
A7: 3 | B7: Bambú Estructural | C7: 50 | D7: 0.5 | E7: 7 | F7: 5.5 | G7: 1.5 | H7: 10 | I7: Sí - cultivo nacional abundante
A8: 4 | B8: Concreto con Biochar (carbón vegetal pirolizado como sustituto parcial de cemento) | C8: 180 | D8: 1.8 | E8: 7 | F8: 5.5 | G8: 2 | H8: 8 | I8: Parcial - producción emergente
A9: 5 | B9: Vidrio Reciclado Triturado como Sustituto de Árido Fino en Concreto y Morteros | C9: 280 | D9: 1 | E9: 6.5 | F9: 3.5 | G9: 2.5 | H9: 9 | I9: Sí - industria reciclaje local
A10: 6 | B10: Hempcrete: Biocompuesto de Cáñamo Industrial y Cal Hidráulica | C10: 40 | D10: 0.8 | E10: 5.5 | F10: 7.5 | G10: 1.5 | H10: 6 | I10: No masiva - cultivo restringido en CO
A11: 7 | B11: Ceniza de Cáscara de Arroz (Rice Husk Ash - RHA) | C11: 210 | D11: 0.6 | E11: 7 | F11: 3 | G11: 2.5 | H11: 7 | I11: Sí - subproducto agroindustrial CO
A12: 8 | B12: Fibras de Refuerzo de Plástico Reciclado | C12: 240 | D12: 2.5 | E12: 6 | F12: 3.5 | G12: 4.5 | H12: 7 | I12: Sí - industria reciclaje activa en CO

Sheet 8.M1 Frecuencia Ponderada
A1: M1 – FRECUENCIA PONDERADA DE MATERIALES
A3: # | B3: Material | C3: Cantidad menciones | D3: Score | E3: M1 (%)
A4: 1 | B4: ='7. Matriz Datos Entrada'!B5 -> Concreto con Agregados de Concreto Reciclado (Residuos de Construcción y Demolición – RCD) | C4: ='7. Matriz Datos Entrada'!H5 -> 18 | D4: =C4/34 -> 0.52941176 | E4: =D4/SUM(D4:D11) -> 0.2278481
A5: 2 | B5: ='7. Matriz Datos Entrada'!B6 -> Geopolímeros Activados Alcalinamente (base escoria de alto horno y/o ceniza volante) | C5: ='7. Matriz Datos Entrada'!H6 -> 14 | D5: =C5/34 -> 0.41176471 | E5: =D5/SUM(D4:D11) -> 0.17721519
A6: 3 | B6: ='7. Matriz Datos Entrada'!B7 -> Bambú Estructural | C6: ='7. Matriz Datos Entrada'!H7 -> 10 | D6: =C6/34 -> 0.29411765 | E6: =D6/SUM(D4:D11) -> 0.12658228
A7: 4 | B7: ='7. Matriz Datos Entrada'!B8 -> Concreto con Biochar (carbón vegetal pirolizado como sustituto parcial de cemento) | C7: ='7. Matriz Datos Entrada'!H8 -> 8 | D7: =C7/34 -> 0.23529412 | E7: =D7/SUM(D4:D11) -> 0.10126582
A8: 5 | B8: ='7. Matriz Datos Entrada'!B9 -> Vidrio Reciclado Triturado como Sustituto de Árido Fino en Concreto y Morteros | C8: ='7. Matriz Datos Entrada'!H9 -> 9 | D8: =C8/34 -> 0.26470588 | E8: =D8/SUM(D4:D11) -> 0.11392405
A9: 6 | B9: ='7. Matriz Datos Entrada'!B10 -> Hempcrete: Biocompuesto de Cáñamo Industrial y Cal Hidráulica | C9: ='7. Matriz Datos Entrada'!H10 -> 6 | D9: =C9/34 -> 0.17647059 | E9: =D9/SUM(D4:D11) -> 0.075949367
A10: 7 | B10: ='7. Matriz Datos Entrada'!B11 -> Ceniza de Cáscara de Arroz (Rice Husk Ash - RHA) | C10: ='7. Matriz Datos Entrada'!H11 -> 7 | D10: =C10/34 -> 0.20588235 | E10: =D10/SUM(D4:D11) -> 0.088607595
A11: 8 | B11: ='7. Matriz Datos Entrada'!B12 -> Fibras de Refuerzo de Plástico Reciclado | C11: ='7. Matriz Datos Entrada'!H12 -> 7 | D11: =C11/34 -> 0.20588235 | E11: =D11/SUM(D4:D11) -> 0.088607595
B12: TOTAL | E12: =SUM(E4:E11) -> 1

Sheet 9.M2 Entropia Shannon
A1: M2 – ENTROPÍA DE SHANNON DE MATERIALES
A3: # | B3: Material | C3: p(●) | D3: p(–) | E3: -p●·ln(p●) | F3: -p–·ln(p–) | G3: Hi (Entropía) | H3: M2 (%)
A4: 1 | B4: ='7. Matriz Datos Entrada'!B5 -> Concreto con Agregados de Concreto Reciclado (Residuos de Construcción y Demolición – RCD) | C4: ='7. Matriz Datos Entrada'!H5/34 -> 0.52941176 | D4: =(34-'7. Matriz Datos Entrada'!H5)/34 -> 0.47058824 | E4: =IF(C4>0,-C4*LN(C4),0) -> 0.33669994 | F4: =IF(D4>0,-D4*LN(D4),0) -> 0.35471614 | G4: =E4+F4 -> 0.69141608 | H4: =(LN(34)-G4)/(8*LN(34)-SUM(G4:G11)) -> 0.11997347
A5: 2 | B5: ='7. Matriz Datos Entrada'!B6 -> Geopolímeros Activados Alcalinamente (base escoria de alto horno y/o ceniza volante) | C5: ='7. Matriz Datos Entrada'!H6/34 -> 0.41176471 | D5: =(34-'7. Matriz Datos Entrada'!H6)/34 -> 0.58823529 | E5: =IF(C5>0,-C5*LN(C5),0) -> 0.36536014 | F5: =IF(D5>0,-D5*LN(D5),0) -> 0.31213427 | G5: =E5+F5 -> 0.6774944 | H5: =(LN(34)-G5)/(8*LN(34)-SUM(G4:G11)) -> 0.12056263
A6: 3 | B6: ='7. Matriz Datos Entrada'!B7 -> Bambú Estructural | C6: ='7. Matriz Datos Entrada'!H7/34 -> 0.29411765 | D6: =(34-'7. Matriz Datos Entrada'!H7)/34 -> 0.70588235 | E6: =IF(C6>0,-C6*LN(C6),0) -> 0.35993395 | F6: =IF(D6>0,-D6*LN(D6),0) -> 0.24586355 | G6: =E6+F6 -> 0.6057975 | H6: =(LN(34)-G6)/(8*LN(34)-SUM(G4:G11)) -> 0.12359681
A7: 4 | B7: ='7. Matriz Datos Entrada'!B8 -> Concreto con Biochar (carbón vegetal pirolizado como sustituto parcial de cemento) | C7: ='7. Matriz Datos Entrada'!H8/34 -> 0.23529412 | D7: =(34-'7. Matriz Datos Entrada'!H8)/34 -> 0.76470588 | E7: =IF(C7>0,-C7*LN(C7),0) -> 0.34045153 | F7: =IF(D7>0,-D7*LN(D7),0) -> 0.20514305 | G7: =E7+F7 -> 0.54559457 | H7: =(LN(34)-G7)/(8*LN(34)-SUM(G4:G11)) -> 0.12614457
A8: 5 | B8: ='7. Matriz Datos Entrada'!B9 -> Vidrio Reciclado Triturado como Sustituto de Árido Fino en Concreto y Morteros | C8: ='7. Matriz Datos Entrada'!H9/34 -> 0.26470588 | D8: =(34-'7. Matriz Datos Entrada'!H9)/34 -> 0.73529412 | E8: =IF(C8>0,-C8*LN(C8),0) -> 0.3518301 | F8: =IF(D8>0,-D8*LN(D8),0) -> 0.22609169 | G8: =E8+F8 -> 0.57792179 | H8: =(LN(34)-G8)/(8*LN(34)-SUM(G4:G11)) -> 0.12477649
A9: 6 | B9: ='7. Matriz Datos Entrada'!B10 -> Hempcrete: Biocompuesto de Cáñamo Industrial y Cal Hidráulica | C9: ='7. Matriz Datos Entrada'!H10/34 -> 0.17647059 | D9: =(34-'7. Matriz Datos Entrada'!H10)/34 -> 0.82352941 | E9: =IF(C9>0,-C9*LN(C9),0) -> 0.30610607 | F9: =IF(D9>0,-D9*LN(D9),0) -> 0.15989319 | G9: =E9+F9 -> 0.46599926 | H9: =(LN(34)-G9)/(8*LN(34)-SUM(G4:G11)) -> 0.129513
A10: 7 | B10: ='7. Matriz Datos Entrada'!B11 -> Ceniza de Cáscara de Arroz (Rice Husk Ash - RHA) | C10: ='7. Matriz Datos Entrada'!H11/34 -> 0.20588235 | D10: =(34-'7. Matriz Datos Entrada'!H11)/34 -> 0.79411765 | E10: =IF(C10>0,-C10*LN(C10),0) -> 0.32538684 | F10: =IF(D10>0,-D10*LN(D10),0) -> 0.18306291 | G10: =E10+F10 -> 0.50844975 | H10: =(LN(34)-G10)/(8*LN(34)-SUM(G4:G11)) -> 0.12771652
A11: 8 | B11: ='7. Matriz Datos Entrada'!B12 -> Fibras de Refuerzo de Plástico Reciclado | C11: ='7. Matriz Datos Entrada'!H12/34 -> 0.20588235 | D11: =(34-'7. Matriz Datos Entrada'!H12)/34 -> 0.79411765 | E11: =IF(C11>0,-C11*LN(C11),0) -> 0.32538684 | F11: =IF(D11>0,-D11*LN(D11),0) -> 0.18306291 | G11: =E11+F11 -> 0.50844975 | H11: =(LN(34)-G11)/(8*LN(34)-SUM(G4:G11)) -> 0.12771652
B12: TOTAL | H12: =SUM(H4:H11) -> 1

Sheet 10.M3 AHP
A1: M3 – AHP SIMPLIFICADO DE MATERIALES
A3: # | B3: Material | C3: Concreto con Agregados de Concreto Reciclado | D3: Geopolímeros Activados Alcalinamente | E3: Bambú Estructural Laminado | F3: Concreto con Biochar | G3: Vidrio Reciclado Triturado | H3: Hempcrete: Biocompuesto de Cáñamo Industrial y Cal Hidráulica | I3: Ceniza de Cáscara de Arroz | J3: Fibras de Refuerzo de Plástico Reciclado | K3: Suma fila | L3: M3 (%)
A4: 1 | B4: Concreto con Agregados de Concreto Reciclado | C4: ='8.M1 Frecuencia Ponderada'!D4/'8.M1 Frecuencia Ponderada'!D4 -> 1 | D4: ='8.M1 Frecuencia Ponderada'!D4/'8.M1 Frecuencia Ponderada'!D5 -> 1.2857143 | E4: ='8.M1 Frecuencia Ponderada'!D4/'8.M1 Frecuencia Ponderada'!D6 -> 1.8 | F4: ='8.M1 Frecuencia Ponderada'!D4/'8.M1 Frecuencia Ponderada'!D7 -> 2.25 | G4: ='8.M1 Frecuencia Ponderada'!D4/'8.M1 Frecuencia Ponderada'!D8 -> 2 | H4: ='8.M1 Frecuencia Ponderada'!D4/'8.M1 Frecuencia Ponderada'!D9 -> 3 | I4: ='8.M1 Frecuencia Ponderada'!D4/'8.M1 Frecuencia Ponderada'!D10 -> 2.5714286 | J4: ='8.M1 Frecuencia Ponderada'!D4/'8.M1 Frecuencia Ponderada'!D11 -> 2.5714286 | K4: =SUM(C4:J4) -> 16.478571 | L4: =K4/SUM(K4:K11) -> 0.2278481
A5: 2 | B5: Geopolímeros Activados Alcalinamente | C5: ='8.M1 Frecuencia Ponderada'!D5/'8.M1 Frecuencia Ponderada'!D4 -> 0.77777778 | D5: ='8.M1 Frecuencia Ponderada'!D5/'8.M1 Frecuencia Ponderada'!D5 -> 1 | E5: ='8.M1 Frecuencia Ponderada'!D5/'8.M1 Frecuencia Ponderada'!D6 -> 1.4 | F5: ='8.M1 Frecuencia Ponderada'!D5/'8.M1 Frecuencia Ponderada'!D7 -> 1.75 | G5: ='8.M1 Frecuencia Ponderada'!D5/'8.M1 Frecuencia Ponderada'!D8 -> 1.5555556 | H5: ='8.M1 Frecuencia Ponderada'!D5/'8.M1 Frecuencia Ponderada'!D9 -> 2.3333333 | I5: ='8.M1 Frecuencia Ponderada'!D5/'8.M1 Frecuencia Ponderada'!D10 -> 2 | J5: ='8.M1 Frecuencia Ponderada'!D5/'8.M1 Frecuencia Ponderada'!D11 -> 2 | K5: =SUM(C5:J5) -> 12.816667 | L5: =K5/SUM(K4:K11) -> 0.17721519
A6: 3 | B6: Bambú Estructural Laminado | C6: ='8.M1 Frecuencia Ponderada'!D6/'8.M1 Frecuencia Ponderada'!D4 -> 0.55555556 | D6: ='8.M1 Frecuencia Ponderada'!D6/'8.M1 Frecuencia Ponderada'!D5 -> 0.71428571 | E6: ='8.M1 Frecuencia Ponderada'!D6/'8.M1 Frecuencia Ponderada'!D6 -> 1 | F6: ='8.M1 Frecuencia Ponderada'!D6/'8.M1 Frecuencia Ponderada'!D7 -> 1.25 | G6: ='8.M1 Frecuencia Ponderada'!D6/'8.M1 Frecuencia Ponderada'!D8 -> 1.1111111 | H6: ='8.M1 Frecuencia Ponderada'!D6/'8.M1 Frecuencia Ponderada'!D9 -> 1.6666667 | I6: ='8.M1 Frecuencia Ponderada'!D6/'8.M1 Frecuencia Ponderada'!D10 -> 1.4285714 | J6: ='8.M1 Frecuencia Ponderada'!D6/'8.M1 Frecuencia Ponderada'!D11 -> 1.4285714 | K6: =SUM(C6:J6) -> 9.1547619 | L6: =K6/SUM(K4:K11) -> 0.12658228
A7: 4 | B7: Concreto con Biochar | C7: ='8.M1 Frecuencia Ponderada'!D7/'8.M1 Frecuencia Ponderada'!D4 -> 0.44444444 | D7: ='8.M1 Frecuencia Ponderada'!D7/'8.M1 Frecuencia Ponderada'!D5 -> 0.57142857 | E7: ='8.M1 Frecuencia Ponderada'!D7/'8.M1 Frecuencia Ponderada'!D6 -> 0.8 | F7: ='8.M1 Frecuencia Ponderada'!D7/'8.M1 Frecuencia Ponderada'!D7 -> 1 | G7: ='8.M1 Frecuencia Ponderada'!D7/'8.M1 Frecuencia Ponderada'!D8 -> 0.88888889 | H7: ='8.M1 Frecuencia Ponderada'!D7/'8.M1 Frecuencia Ponderada'!D9 -> 1.3333333 | I7: ='8.M1 Frecuencia Ponderada'!D7/'8.M1 Frecuencia Ponderada'!D10 -> 1.1428571 | J7: ='8.M1 Frecuencia Ponderada'!D7/'8.M1 Frecuencia Ponderada'!D11 -> 1.1428571 | K7: =SUM(C7:J7) -> 7.3238095 | L7: =K7/SUM(K4:K11) -> 0.10126582
A8: 5 | B8: Vidrio Reciclado Triturado | C8: ='8.M1 Frecuencia Ponderada'!D8/'8.M1 Frecuencia Ponderada'!D4 -> 0.5 | D8: ='8.M1 Frecuencia Ponderada'!D8/'8.M1 Frecuencia Ponderada'!D5 -> 0.64285714 | E8: ='8.M1 Frecuencia Ponderada'!D8/'8.M1 Frecuencia Ponderada'!D6 -> 0.9 | F8: ='8.M1 Frecuencia Ponderada'!D8/'8.M1 Frecuencia Ponderada'!D7 -> 1.125 | G8: ='8.M1 Frecuencia Ponderada'!D8/'8.M1 Frecuencia Ponderada'!D8 -> 1 | H8: ='8.M1 Frecuencia Ponderada'!D8/'8.M1 Frecuencia Ponderada'!D9 -> 1.5 | I8: ='8.M1 Frecuencia Ponderada'!D8/'8.M1 Frecuencia Ponderada'!D10 -> 1.2857143 | J8: ='8.M1 Frecuencia Ponderada'!D8/'8.M1 Frecuencia Ponderada'!D11 -> 1.2857143 | K8: =SUM(C8:J8) -> 8.2392857 | L8: =K8/SUM(K4:K11) -> 0.11392405
A9: 6 | B9: Hempcrete: Biocompuesto de Cáñamo Industrial y Cal Hidráulica | C9: ='8.M1 Frecuencia Ponderada'!D9/'8.M1 Frecuencia Ponderada'!D4 -> 0.33333333 | D9: ='8.M1 Frecuencia Ponderada'!D9/'8.M1 Frecuencia Ponderada'!D5 -> 0.42857143 | E9: ='8.M1 Frecuencia Ponderada'!D9/'8.M1 Frecuencia Ponderada'!D6 -> 0.6 | F9: ='8.M1 Frecuencia Ponderada'!D9/'8.M1 Frecuencia Ponderada'!D7 -> 0.75 | G9: ='8.M1 Frecuencia Ponderada'!D9/'8.M1 Frecuencia Ponderada'!D8 -> 0.66666667 | H9: ='8.M1 Frecuencia Ponderada'!D9/'8.M1 Frecuencia Ponderada'!D9 -> 1 | I9: ='8.M1 Frecuencia Ponderada'!D9/'8.M1 Frecuencia Ponderada'!D10 -> 0.85714286 | J9: ='8.M1 Frecuencia Ponderada'!D9/'8.M1 Frecuencia Ponderada'!D11 -> 0.85714286 | K9: =SUM(C9:J9) -> 5.4928571 | L9: =K9/SUM(K4:K11) -> 0.075949367
A10: 7 | B10: Ceniza de Cáscara de Arroz | C10: ='8.M1 Frecuencia Ponderada'!D10/'8.M1 Frecuencia Ponderada'!D4 -> 0.38888889 | D10: ='8.M1 Frecuencia Ponderada'!D10/'8.M1 Frecuencia Ponderada'!D5 -> 0.5 | E10: ='8.M1 Frecuencia Ponderada'!D10/'8.M1 Frecuencia Ponderada'!D6 -> 0.7 | F10: ='8.M1 Frecuencia Ponderada'!D10/'8.M1 Frecuencia Ponderada'!D7 -> 0.875 | G10: ='8.M1 Frecuencia Ponderada'!D10/'8.M1 Frecuencia Ponderada'!D8 -> 0.77777778 | H10: ='8.M1 Frecuencia Ponderada'!D10/'8.M1 Frecuencia Ponderada'!D9 -> 1.1666667 | I10: ='8.M1 Frecuencia Ponderada'!D10/'8.M1 Frecuencia Ponderada'!D10 -> 1 | J10: ='8.M1 Frecuencia Ponderada'!D10/'8.M1 Frecuencia Ponderada'!D11 -> 1 | K10: =SUM(C10:J10) -> 6.4083333 | L10: =K10/SUM(K4:K11) -> 0.088607595
A11: 8 | B11: Fibras de Refuerzo de Plástico Reciclado | C11: ='8.M1 Frecuencia Ponderada'!D11/'8.M1 Frecuencia Ponderada'!D4 -> 0.38888889 | D11: ='8.M1 Frecuencia Ponderada'!D11/'8.M1 Frecuencia Ponderada'!D5 -> 0.5 | E11: ='8.M1 Frecuencia Ponderada'!D11/'8.M1 Frecuencia Ponderada'!D6 -> 0.7 | F11: ='8.M1 Frecuencia Ponderada'!D11/'8.M1 Frecuencia Ponderada'!D7 -> 0.875 | G11: ='8.M1 Frecuencia Ponderada'!D11/'8.M1 Frecuencia Ponderada'!D8 -> 0.77777778 | H11: ='8.M1 Frecuencia Ponderada'!D11/'8.M1 Frecuencia Ponderada'!D9 -> 1.1666667 | I11: ='8.M1 Frecuencia Ponderada'!D11/'8.M1 Frecuencia Ponderada'!D10 -> 1 | J11: ='8.M1 Frecuencia Ponderada'!D11/'8.M1 Frecuencia Ponderada'!D11 -> 1 | K11: =SUM(C11:J11) -> 6.4083333 | L11: =K11/SUM(K4:K11) -> 0.088607595
B12: TOTAL | L12: =SUM(L4:L11) -> 1

Sheet 11. Peso Final Combinado
A1: PESO COMBINADO DE MATERIALES – w_final = 0.40·M1 + 0.30·M2 + 0.30·M3
A2: Pond. M1 → | B2: 0.4 | C2: Pond. M2 → | D2: 0.3 | E2: Pond. M3 → | F2: 0.3
A3: # | B3: Material | C3: M1 – Frec.Pond. | D3: M2 – Entropía | E3: M3 – AHP | F3: PESO FINAL MATERIAL (%)
A4: 1 | B4: ='7. Matriz Datos Entrada'!B5 -> Concreto con Agregados de Concreto Reciclado (Residuos de Construcción y Demolición – RCD) | C4: ='8.M1 Frecuencia Ponderada'!E4 -> 0.2278481 | D4: ='9.M2 Entropia Shannon'!H4 -> 0.11997347 | E4: ='10.M3 AHP'!L4 -> 0.2278481 | F4: =$B$2*C4+$D$2*D4+$F$2*E4 -> 0.19548571
A5: 2 | B5: ='7. Matriz Datos Entrada'!B6 -> Geopolímeros Activados Alcalinamente (base escoria de alto horno y/o ceniza volante) | C5: ='8.M1 Frecuencia Ponderada'!E5 -> 0.17721519 | D5: ='9.M2 Entropia Shannon'!H5 -> 0.12056263 | E5: ='10.M3 AHP'!L5 -> 0.17721519 | F5: =$B$2*C5+$D$2*D5+$F$2*E5 -> 0.16021942
A6: 3 | B6: ='7. Matriz Datos Entrada'!B7 -> Bambú Estructural | C6: ='8.M1 Frecuencia Ponderada'!E6 -> 0.12658228 | D6: ='9.M2 Entropia Shannon'!H6 -> 0.12359681 | E6: ='10.M3 AHP'!L6 -> 0.12658228 | F6: =$B$2*C6+$D$2*D6+$F$2*E6 -> 0.12568664
A7: 4 | B7: ='7. Matriz Datos Entrada'!B8 -> Concreto con Biochar (carbón vegetal pirolizado como sustituto parcial de cemento) | C7: ='8.M1 Frecuencia Ponderada'!E7 -> 0.10126582 | D7: ='9.M2 Entropia Shannon'!H7 -> 0.12614457 | E7: ='10.M3 AHP'!L7 -> 0.10126582 | F7: =$B$2*C7+$D$2*D7+$F$2*E7 -> 0.10872945
A8: 5 | B8: ='7. Matriz Datos Entrada'!B9 -> Vidrio Reciclado Triturado como Sustituto de Árido Fino en Concreto y Morteros | C8: ='8.M1 Frecuencia Ponderada'!E8 -> 0.11392405 | D8: ='9.M2 Entropia Shannon'!H8 -> 0.12477649 | E8: ='10.M3 AHP'!L8 -> 0.11392405 | F8: =$B$2*C8+$D$2*D8+$F$2*E8 -> 0.11717978
A9: 6 | B9: ='7. Matriz Datos Entrada'!B10 -> Hempcrete: Biocompuesto de Cáñamo Industrial y Cal Hidráulica | C9: ='8.M1 Frecuencia Ponderada'!E9 -> 0.075949367 | D9: ='9.M2 Entropia Shannon'!H9 -> 0.129513 | E9: ='10.M3 AHP'!L9 -> 0.075949367 | F9: =$B$2*C9+$D$2*D9+$F$2*E9 -> 0.092018457
A10: 7 | B10: ='7. Matriz Datos Entrada'!B11 -> Ceniza de Cáscara de Arroz (Rice Husk Ash - RHA) | C10: ='8.M1 Frecuencia Ponderada'!E10 -> 0.088607595 | D10: ='9.M2 Entropia Shannon'!H10 -> 0.12771652 | E10: ='10.M3 AHP'!L10 -> 0.088607595 | F10: =$B$2*C10+$D$2*D10+$F$2*E10 -> 0.10034027
A11: 8 | B11: ='7. Matriz Datos Entrada'!B12 -> Fibras de Refuerzo de Plástico Reciclado | C11: ='8.M1 Frecuencia Ponderada'!E11 -> 0.088607595 | D11: ='9.M2 Entropia Shannon'!H11 -> 0.12771652 | E11: ='10.M3 AHP'!L11 -> 0.088607595 | F11: =$B$2*C11+$D$2*D11+$F$2*E11 -> 0.10034027
B12: TOTAL | C12: =SUM(C4:C11) -> 1 | D12: =SUM(D4:D11) -> 1 | E12: =SUM(E4:E11) -> 1 | F12: =SUM(F4:F11) -> 1

Sheet 14_Mat_TOPSIS
A1: TOPSIS – RANKING OBJETIVO DE MATERIALES
A2: Technique for Order Preference by Similarity to Ideal Solution | Pasos: 1) Normalizar 2) Ponderar 3) Solución ideal/anti-ideal 4) Distancias 5) Índice Ci
A4: PASO 1 – NORMALIZACIÓN VECTORIAL: rij = xij / √(Σ xij²)
A5: # | B5: Material | C5: Emisiones de CO₂ equivalente | D5: Energía Embebida | E5: Desempeño Técnico y Mecánico | F5: Costo del Ciclo de Vida | G5: Impacto en Salud Humana y Ecosistemas
A6: Dirección → | B6: Peso criterio → | C6: MIN | D6: MIN | E6: MAX | F6: MIN | G6: MIN
A7: PESOS → | B7: (de hoja 5) | C7: ='5. Peso Final Combinado'!E4 -> 0.34022249 | D7: ='5. Peso Final Combinado'!E5 -> 0.20462612 | E7: ='5. Peso Final Combinado'!E6 -> 0.18648624 | F7: ='5. Peso Final Combinado'!E7 -> 0.15982399 | G7: ='5. Peso Final Combinado'!E8 -> 0.10884116
A8: 1 | B8: ='7. Matriz Datos Entrada'!B5 -> Concreto con Agregados de Concreto Reciclado (Residuos de Construcción y Demolición – RCD) | C8: ='7. Matriz Datos Entrada'!C5/SQRT(SUMPRODUCT('7. Matriz Datos Entrada'!C5:C12,'7. Matriz Datos Entrada'!C5:C12)) -> 0.55789444 | D8: ='7. Matriz Datos Entrada'!D5/SQRT(SUMPRODUCT('7. Matriz Datos Entrada'!D5:D12,'7. Matriz Datos Entrada'!D5:D12)) -> 0.23796225 | E8: ='7. Matriz Datos Entrada'!E5/SQRT(SUMPRODUCT('7. Matriz Datos Entrada'!E5:E12,'7. Matriz Datos Entrada'!E5:E12)) -> 0.38691162 | F8: ='7. Matriz Datos Entrada'!F5/SQRT(SUMPRODUCT('7. Matriz Datos Entrada'!F5:F12,'7. Matriz Datos Entrada'!F5:F12)) -> 0.28126502 | G8: ='7. Matriz Datos Entrada'!G5/SQRT(SUMPRODUCT('7. Matriz Datos Entrada'!G5:G12,'7. Matriz Datos Entrada'!G5:G12)) -> 0.44271887
A9: 2 | B9: ='7. Matriz Datos Entrada'!B6 -> Geopolímeros Activados Alcalinamente (base escoria de alto horno y/o ceniza volante) | C9: ='7. Matriz Datos Entrada'!C6/SQRT(SUMPRODUCT('7. Matriz Datos Entrada'!C5:C12,'7. Matriz Datos Entrada'!C5:C12)) -> 0.17434201 | D9: ='7. Matriz Datos Entrada'!D6/SQRT(SUMPRODUCT('7. Matriz Datos Entrada'!D5:D12,'7. Matriz Datos Entrada'!D5:D12)) -> 0.69405656 | E9: ='7. Matriz Datos Entrada'!E6/SQRT(SUMPRODUCT('7. Matriz Datos Entrada'!E5:E12,'7. Matriz Datos Entrada'!E5:E12)) -> 0.41270572 | F9: ='7. Matriz Datos Entrada'!F6/SQRT(SUMPRODUCT('7. Matriz Datos Entrada'!F5:F12,'7. Matriz Datos Entrada'!F5:F12)) -> 0.42189753 | G9: ='7. Matriz Datos Entrada'!G6/SQRT(SUMPRODUCT('7. Matriz Datos Entrada'!G5:G12,'7. Matriz Datos Entrada'!G5:G12)) -> 0.37947332
A10: 3 | B10: ='7. Matriz Datos Entrada'!B7 -> Bambú Estructural | C10: ='7. Matriz Datos Entrada'!C7/SQRT(SUMPRODUCT('7. Matriz Datos Entrada'!C5:C12,'7. Matriz Datos Entrada'!C5:C12)) -> 0.087171005 | D10: ='7. Matriz Datos Entrada'!D7/SQRT(SUMPRODUCT('7. Matriz Datos Entrada'!D5:D12,'7. Matriz Datos Entrada'!D5:D12)) -> 0.099150937 | E10: ='7. Matriz Datos Entrada'!E7/SQRT(SUMPRODUCT('7. Matriz Datos Entrada'!E5:E12,'7. Matriz Datos Entrada'!E5:E12)) -> 0.36111751 | F10: ='7. Matriz Datos Entrada'!F7/SQRT(SUMPRODUCT('7. Matriz Datos Entrada'!F5:F12,'7. Matriz Datos Entrada'!F5:F12)) -> 0.3867394 | G10: ='7. Matriz Datos Entrada'!G7/SQRT(SUMPRODUCT('7. Matriz Datos Entrada'!G5:G12,'7. Matriz Datos Entrada'!G5:G12)) -> 0.18973666
A11: 4 | B11: ='7. Matriz Datos Entrada'!B8 -> Concreto con Biochar (carbón vegetal pirolizado como sustituto parcial de cemento) | C11: ='7. Matriz Datos Entrada'!C8/SQRT(SUMPRODUCT('7. Matriz Datos Entrada'!C5:C12,'7. Matriz Datos Entrada'!C5:C12)) -> 0.31381562 | D11: ='7. Matriz Datos Entrada'!D8/SQRT(SUMPRODUCT('7. Matriz Datos Entrada'!D5:D12,'7. Matriz Datos Entrada'!D5:D12)) -> 0.35694337 | E11: ='7. Matriz Datos Entrada'!E8/SQRT(SUMPRODUCT('7. Matriz Datos Entrada'!E5:E12,'7. Matriz Datos Entrada'!E5:E12)) -> 0.36111751 | F11: ='7. Matriz Datos Entrada'!F8/SQRT(SUMPRODUCT('7. Matriz Datos Entrada'!F5:F12,'7. Matriz Datos Entrada'!F5:F12)) -> 0.3867394 | G11: ='7. Matriz Datos Entrada'!G8/SQRT(SUMPRODUCT('7. Matriz Datos Entrada'!G5:G12,'7. Matriz Datos Entrada'!G5:G12)) -> 0.25298221
A12: 5 | B12: ='7. Matriz Datos Entrada'!B9 -> Vidrio Reciclado Triturado como Sustituto de Árido Fino en Concreto y Morteros | C12: ='7. Matriz Datos Entrada'!C9/SQRT(SUMPRODUCT('7. Matriz Datos Entrada'!C5:C12,'7. Matriz Datos Entrada'!C5:C12)) -> 0.48815763 | D12: ='7. Matriz Datos Entrada'!D9/SQRT(SUMPRODUCT('7. Matriz Datos Entrada'!D5:D12,'7. Matriz Datos Entrada'!D5:D12)) -> 0.19830187 | E12: ='7. Matriz Datos Entrada'!E9/SQRT(SUMPRODUCT('7. Matriz Datos Entrada'!E5:E12,'7. Matriz Datos Entrada'!E5:E12)) -> 0.3353234 | F12: ='7. Matriz Datos Entrada'!F9/SQRT(SUMPRODUCT('7. Matriz Datos Entrada'!F5:F12,'7. Matriz Datos Entrada'!F5:F12)) -> 0.24610689 | G12: ='7. Matriz Datos Entrada'!G9/SQRT(SUMPRODUCT('7. Matriz Datos Entrada'!G5:G12,'7. Matriz Datos Entrada'!G5:G12)) -> 0.31622777
A13: 6 | B13: ='7. Matriz Datos Entrada'!B10 -> Hempcrete: Biocompuesto de Cáñamo Industrial y Cal Hidráulica | C13: ='7. Matriz Datos Entrada'!C10/SQRT(SUMPRODUCT('7. Matriz Datos Entrada'!C5:C12,'7. Matriz Datos Entrada'!C5:C12)) -> 0.069736804 | D13: ='7. Matriz Datos Entrada'!D10/SQRT(SUMPRODUCT('7. Matriz Datos Entrada'!D5:D12,'7. Matriz Datos Entrada'!D5:D12)) -> 0.1586415 | E13: ='7. Matriz Datos Entrada'!E10/SQRT(SUMPRODUCT('7. Matriz Datos Entrada'!E5:E12,'7. Matriz Datos Entrada'!E5:E12)) -> 0.28373519 | F13: ='7. Matriz Datos Entrada'!F10/SQRT(SUMPRODUCT('7. Matriz Datos Entrada'!F5:F12,'7. Matriz Datos Entrada'!F5:F12)) -> 0.52737192 | G13: ='7. Matriz Datos Entrada'!G10/SQRT(SUMPRODUCT('7. Matriz Datos Entrada'!G5:G12,'7. Matriz Datos Entrada'!G5:G12)) -> 0.18973666
A14: 7 | B14: ='7. Matriz Datos Entrada'!B11 -> Ceniza de Cáscara de Arroz (Rice Husk Ash - RHA) | C14: ='7. Matriz Datos Entrada'!C11/SQRT(SUMPRODUCT('7. Matriz Datos Entrada'!C5:C12,'7. Matriz Datos Entrada'!C5:C12)) -> 0.36611822 | D14: ='7. Matriz Datos Entrada'!D11/SQRT(SUMPRODUCT('7. Matriz Datos Entrada'!D5:D12,'7. Matriz Datos Entrada'!D5:D12)) -> 0.11898112 | E14: ='7. Matriz Datos Entrada'!E11/SQRT(SUMPRODUCT('7. Matriz Datos Entrada'!E5:E12,'7. Matriz Datos Entrada'!E5:E12)) -> 0.36111751 | F14: ='7. Matriz Datos Entrada'!F11/SQRT(SUMPRODUCT('7. Matriz Datos Entrada'!F5:F12,'7. Matriz Datos Entrada'!F5:F12)) -> 0.21094877 | G14: ='7. Matriz Datos Entrada'!G11/SQRT(SUMPRODUCT('7. Matriz Datos Entrada'!G5:G12,'7. Matriz Datos Entrada'!G5:G12)) -> 0.31622777
A15: 8 | B15: ='7. Matriz Datos Entrada'!B12 -> Fibras de Refuerzo de Plástico Reciclado | C15: ='7. Matriz Datos Entrada'!C12/SQRT(SUMPRODUCT('7. Matriz Datos Entrada'!C5:C12,'7. Matriz Datos Entrada'!C5:C12)) -> 0.41842083 | D15: ='7. Matriz Datos Entrada'!D12/SQRT(SUMPRODUCT('7. Matriz Datos Entrada'!D5:D12,'7. Matriz Datos Entrada'!D5:D12)) -> 0.49575469 | E15: ='7. Matriz Datos Entrada'!E12/SQRT(SUMPRODUCT('7. Matriz Datos Entrada'!E5:E12,'7. Matriz Datos Entrada'!E5:E12)) -> 0.30952929 | F15: ='7. Matriz Datos Entrada'!F12/SQRT(SUMPRODUCT('7. Matriz Datos Entrada'!F5:F12,'7. Matriz Datos Entrada'!F5:F12)) -> 0.24610689 | G15: ='7. Matriz Datos Entrada'!G12/SQRT(SUMPRODUCT('7. Matriz Datos Entrada'!G5:G12,'7. Matriz Datos Entrada'!G5:G12)) -> 0.56920998
A17: PASO 2 – MATRIZ PONDERADA: vij = wj × rij
A18: # | B18: Material | C18: CO₂ / GWP | D18: Energía Emb. | E18: Desempeño Téc. | F18: Costo (LCC) | G18: Salud / Eco.
A19: 1 | B19: ='7. Matriz Datos Entrada'!B5 -> Concreto con Agregados de Concreto Reciclado (Residuos de Construcción y Demolición – RCD) | C19: ='5. Peso Final Combinado'!E4*C8 -> 0.18980823 | D19: ='5. Peso Final Combinado'!E5*D8 -> 0.048693291 | E19: ='5. Peso Final Combinado'!E6*E8 -> 0.072153694 | F19: ='5. Peso Final Combinado'!E7*F8 -> 0.044952897 | G19: ='5. Peso Final Combinado'!E8*G8 -> 0.048186037
A20: 2 | B20: ='7. Matriz Datos Entrada'!B6 -> Geopolímeros Activados Alcalinamente (base escoria de alto horno y/o ceniza volante) | C20: ='5. Peso Final Combinado'!E4*C9 -> 0.059315073 | D20: ='5. Peso Final Combinado'!E5*D9 -> 0.1420221 | E20: ='5. Peso Final Combinado'!E6*E9 -> 0.07696394 | F20: ='5. Peso Final Combinado'!E7*F9 -> 0.067429346 | G20: ='5. Peso Final Combinado'!E8*G9 -> 0.041302318
A21: 3 | B21: ='7. Matriz Datos Entrada'!B7 -> Bambú Estructural | C21: ='5. Peso Final Combinado'!E4*C10 -> 0.029657536 | D21: ='5. Peso Final Combinado'!E5*D10 -> 0.020288871 | E21: ='5. Peso Final Combinado'!E6*E10 -> 0.067343447 | F21: ='5. Peso Final Combinado'!E7*F10 -> 0.061810234 | G21: ='5. Peso Final Combinado'!E8*G10 -> 0.020651159
A22: 4 | B22: ='7. Matriz Datos Entrada'!B8 -> Concreto con Biochar (carbón vegetal pirolizado como sustituto parcial de cemento) | C22: ='5. Peso Final Combinado'!E4*C11 -> 0.10676713 | D22: ='5. Peso Final Combinado'!E5*D11 -> 0.073039937 | E22: ='5. Peso Final Combinado'!E6*E11 -> 0.067343447 | F22: ='5. Peso Final Combinado'!E7*F11 -> 0.061810234 | G22: ='5. Peso Final Combinado'!E8*G11 -> 0.027534879
A23: 5 | B23: ='7. Matriz Datos Entrada'!B9 -> Vidrio Reciclado Triturado como Sustituto de Árido Fino en Concreto y Morteros | C23: ='5. Peso Final Combinado'!E4*C12 -> 0.1660822 | D23: ='5. Peso Final Combinado'!E5*D12 -> 0.040577743 | E23: ='5. Peso Final Combinado'!E6*E12 -> 0.062533201 | F23: ='5. Peso Final Combinado'!E7*F12 -> 0.039333785 | G23: ='5. Peso Final Combinado'!E8*G12 -> 0.034418598
A24: 6 | B24: ='7. Matriz Datos Entrada'!B10 -> Hempcrete: Biocompuesto de Cáñamo Industrial y Cal Hidráulica | C24: ='5. Peso Final Combinado'!E4*C13 -> 0.023726029 | D24: ='5. Peso Final Combinado'!E5*D13 -> 0.032462194 | E24: ='5. Peso Final Combinado'!E6*E13 -> 0.052912709 | F24: ='5. Peso Final Combinado'!E7*F13 -> 0.084286682 | G24: ='5. Peso Final Combinado'!E8*G13 -> 0.020651159
A25: 7 | B25: ='7. Matriz Datos Entrada'!B11 -> Ceniza de Cáscara de Arroz (Rice Husk Ash - RHA) | C25: ='5. Peso Final Combinado'!E4*C14 -> 0.12456165 | D25: ='5. Peso Final Combinado'!E5*D14 -> 0.024346646 | E25: ='5. Peso Final Combinado'!E6*E14 -> 0.067343447 | F25: ='5. Peso Final Combinado'!E7*F14 -> 0.033714673 | G25: ='5. Peso Final Combinado'!E8*G14 -> 0.034418598
A26: 8 | B26: ='7. Matriz Datos Entrada'!B12 -> Fibras de Refuerzo de Plástico Reciclado | C26: ='5. Peso Final Combinado'!E4*C15 -> 0.14235617 | D26: ='5. Peso Final Combinado'!E5*D15 -> 0.10144436 | E26: ='5. Peso Final Combinado'!E6*E15 -> 0.057722955 | F26: ='5. Peso Final Combinado'!E7*F15 -> 0.039333785 | G26: ='5. Peso Final Combinado'!E8*G15 -> 0.061953477
A28: PASO 3 – SOLUCIÓN IDEAL (A+) Y ANTI-IDEAL (A−) | MIN→menor vij es mejor | MAX→mayor vij es mejor
A29: A+ (Ideal) | B29: Mejor valor por criterio | C29: =MIN(C19:C26) -> 0.023726029 | D29: =MIN(D19:D26) -> 0.020288871 | E29: =MAX(E19:E26) -> 0.07696394 | F29: =MIN(F19:F26) -> 0.033714673 | G29: =MIN(G19:G26) -> 0.020651159
A30: A− (Anti-Ideal) | B30: Peor valor por criterio | C30: =MAX(C19:C26) -> 0.18980823 | D30: =MAX(D19:D26) -> 0.1420221 | E30: =MIN(E19:E26) -> 0.052912709 | F30: =MAX(F19:F26) -> 0.084286682 | G30: =MAX(G19:G26) -> 0.061953477
A32: PASO 4 – DISTANCIAS: Di+ = √Σ(vij−Aj+)² | Di− = √Σ(vij−Aj−)²
A33: # | B33: Material | C33: Di+ (dist. a ideal) | D33: Di− (dist. a anti-ideal)
A34: 1 | B34: ='7. Matriz Datos Entrada'!B5 -> Concreto con Agregados de Concreto Reciclado (Residuos de Construcción y Demolición – RCD) | C34: =SQRT((C19-C29)^2+(D19-D29)^2+(E19-E29)^2+(F19-F29)^2+(G19-G29)^2) -> 0.17116575 | D34: =SQRT((C19-C30)^2+(D19-D30)^2+(E19-E30)^2+(F19-F30)^2+(G19-G30)^2) -> 0.10400563
A35: 2 | B35: ='7. Matriz Datos Entrada'!B6 -> Geopolímeros Activados Alcalinamente (base escoria de alto horno y/o ceniza volante) | C35: =SQRT((C20-C29)^2+(D20-D29)^2+(E20-E29)^2+(F20-F29)^2+(G20-G29)^2) -> 0.13284844 | D35: =SQRT((C20-C30)^2+(D20-D30)^2+(E20-E30)^2+(F20-F30)^2+(G20-G30)^2) -> 0.13534241
A36: 3 | B36: ='7. Matriz Datos Entrada'!B7 -> Bambú Estructural | C36: =SQRT((C21-C29)^2+(D21-D29)^2+(E21-E29)^2+(F21-F29)^2+(G21-G29)^2) -> 0.030283613 | D36: =SQRT((C21-C30)^2+(D21-D30)^2+(E21-E30)^2+(F21-F30)^2+(G21-G30)^2) -> 0.20709066
A37: 4 | B37: ='7. Matriz Datos Entrada'!B8 -> Concreto con Biochar (carbón vegetal pirolizado como sustituto parcial de cemento) | C37: =SQRT((C22-C29)^2+(D22-D29)^2+(E22-E29)^2+(F22-F29)^2+(G22-G29)^2) -> 0.10299417 | D37: =SQRT((C22-C30)^2+(D22-D30)^2+(E22-E30)^2+(F22-F30)^2+(G22-G30)^2) -> 0.11641495
A38: 5 | B38: ='7. Matriz Datos Entrada'!B9 -> Vidrio Reciclado Triturado como Sustituto de Árido Fino en Concreto y Morteros | C38: =SQRT((C23-C29)^2+(D23-D29)^2+(E23-E29)^2+(F23-F29)^2+(G23-G29)^2) -> 0.14528001 | D38: =SQRT((C23-C30)^2+(D23-D30)^2+(E23-E30)^2+(F23-F30)^2+(G23-G30)^2) -> 0.11715532
A39: 6 | B39: ='7. Matriz Datos Entrada'!B10 -> Hempcrete: Biocompuesto de Cáñamo Industrial y Cal Hidráulica | C39: =SQRT((C24-C29)^2+(D24-D29)^2+(E24-E29)^2+(F24-F29)^2+(G24-G29)^2) -> 0.057307762 | D39: =SQRT((C24-C30)^2+(D24-D30)^2+(E24-E30)^2+(F24-F30)^2+(G24-G30)^2) -> 0.20320569
A40: 7 | B40: ='7. Matriz Datos Entrada'!B11 -> Ceniza de Cáscara de Arroz (Rice Husk Ash - RHA) | C40: =SQRT((C25-C29)^2+(D25-D29)^2+(E25-E29)^2+(F25-F29)^2+(G25-G29)^2) -> 0.10230535 | D40: =SQRT((C25-C30)^2+(D25-D30)^2+(E25-E30)^2+(F25-F30)^2+(G25-G30)^2) -> 0.14706656
A41: 8 | B41: ='7. Matriz Datos Entrada'!B12 -> Fibras de Refuerzo de Plástico Reciclado | C41: =SQRT((C26-C29)^2+(D26-D29)^2+(E26-E29)^2+(F26-F29)^2+(G26-G29)^2) -> 0.15088736 | D41: =SQRT((C26-C30)^2+(D26-D30)^2+(E26-E30)^2+(F26-F30)^2+(G26-G30)^2) -> 0.077085358
A43: PASO 5 – ÍNDICE DE CLOSENESS: Ci = Di− / (Di+ + Di−) | Ci → 1 = mejor | Ci → 0 = peor
A44: # | B44: Material | C44: Di+ | D44: Di− | E44: Ci (Índice) | F44: RANKING | G44: % Aparece en estudios
A45: 1 | B45: ='7. Matriz Datos Entrada'!B5 -> Concreto con Agregados de Concreto Reciclado (Residuos de Construcción y Demolición – RCD) | C45: =C34 -> 0.17116575 | D45: =D34 -> 0.10400563 | E45: =D45/(C45+D45) -> 0.37796674 | F45: =RANK(E45,E45:E52,0) -> 7 | G45: =('7. Matriz Datos Entrada'!H5+'7. Matriz Datos Entrada'!#REF!*0.5)/34 -> #REF!
...

Sheet 12_Justificacion_Materiales
A1: JUSTIFICACIÓN SÓLIDA DE SELECCIÓN DE MATERIALES
A2: Consolidación de evidencia: frecuencia en literatura + desempeño MCDM + viabilidad local + pesos de criterios
A4: Concreto con RCA (Agregados Reciclados)
B5: ✓ Aparece en 18/34 fuentes con cobertura fuerte (53% de estudios).
B6: ✓ Reduce CO₂ ~30% vs. concreto convencional (320 vs ~480 kg CO₂-eq/ton).
B7: ✓ Alta disponibilidad en mercado colombiano (RCD urbano).
B8: ✓ Mayor peso M1 (freq. ponderada) por su alta presencia en literatura.
B9: ✓ Soportado por [Adesope 2025, Arab 2025, Silva 2024, Luque 2025].
A11: Geopolímeros (base escoria/ceniza)
B12: ✓ Aparece en 14/34 fuentes fuertes (41% de estudios).
B13: ✓ Reducción hasta 80% de CO₂ frente al cemento Portland (criterio peso 24.47%).
B14: ✓ Alta resistencia química/mecánica — Desempeño Técnico (peso 20.96%).
B15: ✓ Disponibilidad parcial en Colombia: requiere escoria siderúrgica o ceniza volante.
B16: ✓ Soportado por [Ugural 2024, Demirtürk 2025, Ben Rjiba 2026].
A18: Bambú Estructural
B19: ✓ Aparece en 10/34 fuentes fuertes (29% de estudios).
B20: ✓ CO₂ más bajo del conjunto (~50 kg CO₂-eq/ton). Material carbono-negativo.
B21: ✓ Colombia: productor natural con alta disponibilidad rural/regional.
B22: ✓ Peso Salud/Eco (13.51%) favorecido: mínimo impacto ecosistémico.
B23: ✓ Soportado por [Takano 2025, Sharma 2021].
A25: Concreto con Biochar
B26: ✓ Aparece en 8/34 fuentes fuertes (24% de estudios).
B27: ✓ Captura de carbono durante producción: CO₂ neto ~180 kg CO₂-eq/ton.
B28: ✓ Frontera técnica emergente 2024-2026: alineado con criterio Salud/Eco.
B29: ✓ Disponibilidad parcial — producción emergente en Colombia.
B30: ✓ Soportado por [Ben Rjiba 2026, Mekky 2025, Gupta 2021].
A32: Vidrio Reciclado (en concreto/morteros)
B33: ✓ Aparece en 9/34 fuentes fuertes (26% de estudios).
B34: ✓ Reduce residuos sólidos industriales. CO₂ moderado (~280 kg CO₂-eq/ton).
B35: ✓ Alta disponibilidad en industria de reciclaje colombiana.
B36: ✓ Integración sencilla en normativa de construcción existente.
B37: ✓ Soportado por [Ben Rjiba 2026, Aliabdo 2021].
A39: Hempcrete (Cáñamo + Cal)
B40: ✓ Aparece en 6/34 fuentes fuertes (18% de estudios).
B41: ✓ Carbono NEGATIVO: captura más CO₂ del que emite durante su ciclo de vida.
B42: ✓ Excelente aislamiento térmico (criterio Energía Emb. peso 21.88%).
B43: ✓ LIMITANTE: cultivo restringido en Colombia — disponibilidad no masiva.
B44: ✓ Soportado por [Dinh 2020, Arrigoni 2021].
A46: Ceniza de Cáscara de Arroz (RHA)
B47: ✓ Aparece en 7/34 fuentes fuertes (21% de estudios).
...
